# Python: bare except 语句——为什么不好。

> 原文:[https://dev . to/Moser/python-bare-except-statement-why-it-is-bad-17m 2](https://dev.to/moser/python-bare-except-statement-why-it-is-bad-17m2)

裸露的`except`语句是我经常在应该无限期运行的脚本的主循环中看到的。关于这个问题，皮林特会警告你，但是在我看来，我们应该开始把它当作一个错误。

考虑下面的代码片段:

```
import sys
import time

def risky_business():
  time.sleep(1)

while(True):
  try:
    risky_business()
  except:
    print("Problems?", sys.exc_info()) 
```

这将很好地保持你的程序运行，不管在你的`risky_business`函数中发生了什么。但是让我们试着通过按 CTRL-C 来停止你的程序

```
$ python a.py 
^C('Problems?', (<type 'exceptions.KeyboardInterrupt'>, KeyboardInterrupt(), <traceback object at 0x7f234f6c9dd0>)) 
```

我们抓住了这个异常，然后继续前进。但是我们抓了更多不该抓的东西。让我们尝试从业务功能中退出程序，可能是因为用户要求这样做，或者我们得到了信号。

```
def risky_business():
  time.sleep(1)
  sys.exit(0) 
```

```
$ python a.py 
('Problems?', (<type 'exceptions.SystemExit'>, SystemExit(0,), <traceback object at 0x7f49b7ab5e18>))
('Problems?', (<type 'exceptions.SystemExit'>, SystemExit(0,), <traceback object at 0x7f49b7ab5ea8>))
... 
```

那么，为什么会出现这种情况呢？`KeyboardInterrupt`和`SystemExit`都是例外(来源于`BaseException`)。一个没有任何限制的`except`语句将捕获任何来自`BaseException`的异常。这里是内置异常的完整层次。

我们可以通过限制我们想要捕获的异常类型来解决我们的问题:

```
def risky_business():
  time.sleep(1)

while(True):
  try:
    risky_business()
  except Exception:
    print("Problems?", sys.exc_info()) 
```

当我们现在按 CTRL-C 时，程序退出，并显示正确的异常。

```
$ python a.py
^CTraceback (most recent call last):
  File "a.py", line 10, in <module>
    risky_business()
  File "a.py", line 6, in risky_business
    time.sleep(1)
KeyboardInterrupt 
```

Pylint 仍然会[警告](http://pylint-messages.wikidot.com/messages:w0703)注意这一行，因为捕捉`Exception`仍然非常广泛，只有当你有充分的理由时才应该这样做，例如上面提到的理由(即使服务不能处理某个输入或请求，也要保持服务运行)。

所以下次当你在代码中看到一个空的`except`语句时，花一点时间重新考虑一下你是否真的想抓住`SystemExit`、`KeyboardInterrupt`(还有我上面没有提到的`GeneratorExit`)。如果是这种情况，您可能希望将其显式化，以便下一个阅读代码的人不必再次检查。